<?xml version='1.0' encoding='utf-8'?>
<mujoco model="biped_s48">
  <compiler angle="radian" meshdir="../meshes/" />
  <size njmax="500" nconmax="100" />
  <asset>
    <mesh name="torso" file="torso.STL" />
    <mesh name="l_leg_roll" file="l_leg_roll.STL" />
    <mesh name="l_leg_yaw" file="l_leg_yaw.STL" />
    <mesh name="l_leg_pitch" file="l_leg_pitch.STL" />
    <mesh name="l_knee" file="l_knee.STL" />
    <mesh name="l_foot_pitch" file="l_foot_pitch.STL" />
    <mesh name="l_foot_roll" file="l_foot_roll.STL" />
    <mesh name="r_leg_roll" file="r_leg_roll.STL" />
    <mesh name="r_leg_yaw" file="r_leg_yaw.STL" />
    <mesh name="r_leg_pitch" file="r_leg_pitch.STL" />
    <mesh name="r_knee" file="r_knee.STL" />
    <mesh name="r_foot_pitch" file="r_foot_pitch.STL" />
    <mesh name="r_foot_roll" file="r_foot_roll.STL" />
    <mesh name="l_arm_pitch" file="l_arm_pitch.STL" />
    <mesh name="l_arm_roll" file="l_arm_roll.STL" />
    <mesh name="l_arm_yaw" file="l_arm_yaw.STL" />
    <mesh name="l_forearm" file="l_forearm.STL" />
    <mesh name="l_hand_yaw" file="l_hand_yaw.STL" />
    <mesh name="l_hand_roll" file="l_hand_roll.STL" />
    <mesh name="l_hand_pitch" file="l_hand_pitch.STL" />
    <mesh name="r_arm_pitch" file="r_arm_pitch.STL" />
    <mesh name="r_arm_roll" file="r_arm_roll.STL" />
    <mesh name="r_arm_yaw" file="r_arm_yaw.STL" />
    <mesh name="r_forearm" file="r_forearm.STL" />
    <mesh name="r_hand_yaw" file="r_hand_yaw.STL" />
    <mesh name="r_hand_roll" file="r_hand_roll.STL" />
    <mesh name="r_hand_pitch" file="r_hand_pitch.STL" />
    <mesh name="head_yaw" file="head_yaw.STL" />
    <mesh name="head_pitch" file="head_pitch.STL" />
    <mesh name="camera" file="camera.STL" />
    <mesh name="radar" file="radar.STL" />
    <mesh name="l_palm" file="l_palm.STL" />
    <mesh name="l_thumb_prox" file="l_thumb_prox.STL" />
    <mesh name="l_thumb_dist" file="l_thumb_dist.STL" />
    <mesh name="l_Index_prox" file="l_Index_prox.STL" />
    <mesh name="l_index_dist" file="l_index_dist.STL" />
    <mesh name="l_middle_prox" file="l_middle_prox.STL" />
    <mesh name="l_middle_dist" file="l_middle_dist.STL" />
    <mesh name="l_ring_prox" file="l_ring_prox.STL" />
    <mesh name="l_ring_dist" file="l_ring_dist.STL" />
    <mesh name="l_little_prox" file="l_little_prox.STL" />
    <mesh name="l_little_dist" file="l_little_dist.STL" />
    <mesh name="r_palm" file="r_palm.STL" />
    <mesh name="r_thumb_prox" file="r_thumb_prox.STL" />
    <mesh name="r_thumb_dist" file="r_thumb_dist.STL" />
    <mesh name="r_index_prox" file="r_index_prox.STL" />
    <mesh name="r_index_dist" file="r_index_dist.STL" />
    <mesh name="r_middle_prox" file="r_middle_prox.STL" />
    <mesh name="r_middle_dist" file="r_middle_dist.STL" />
    <mesh name="r_ring_prox" file="r_ring_prox.STL" />
    <mesh name="r_ring_dist" file="r_ring_dist.STL" />
    <mesh name="r_little_prox" file="r_little_prox.STL" />
    <mesh name="r_little_dist" file="r_little_dist.STL" />
  </asset>
  <worldbody>
    <body name="base_link" pos="0 0 0.82">
      <freejoint />
      <site name="imu" pos="0 0 0" />
      <inertial pos="-0.0185005 0.00031952 0.192957" quat="0.998529 4.54328e-05 0.0542216 0.000512508" mass="21.8806" diaginertia="0.938886 0.825905 0.269012" />
      <geom type="mesh" contype="0" conaffinity="0" group="1" density="0" rgba="1 1 1 1" mesh="torso" />
      <body name="leg_l1_link" pos="-0.0024999 0.087 -0.066">
        <inertial pos="-0.00430148 -2.708e-05 -0.00851195" quat="-0.000746146 0.721814 -0.00298446 0.69208" mass="1.71093" diaginertia="0.00371121 0.00277272 0.00205799" />
        <joint name="leg_l1_joint" pos="0 0 0" axis="1 0 0" range="-0.314159 0.663225" actuatorfrcrange="-180 180" damping="0.2" />
        <geom type="mesh" contype="0" conaffinity="0" group="1" density="0" rgba="1 1 1 1" mesh="l_leg_roll" />
        <body name="leg_l2_link">
          <inertial pos="0 -0.00231118 -0.0906254" quat="0.696411 0.717644 -1.38707e-05 1.34603e-05" mass="0.580292" diaginertia="0.00223984 0.00146412 0.00123154" />
          <joint name="leg_l2_joint" pos="0 0 0" axis="0 0 1" range="-0.872665 0.785398" actuatorfrcrange="-100 100" damping="0.2" />
          <geom type="mesh" contype="0" conaffinity="0" group="1" density="0" rgba="1 1 1 1" mesh="l_leg_yaw" />
          <body name="leg_l3_link" pos="0.000500355 -0.001 -0.1287">
            <inertial pos="0.00150537 0.0119961 -0.0841162" quat="0.783717 0.018124 -0.0364866 0.619781" mass="4.50393" diaginertia="0.0396246 0.0389355 0.00980214" />
            <joint name="leg_l3_joint" pos="0 0 0" axis="0 1 0" range="-2.00713 1.5708" actuatorfrcrange="-100 100" damping="0.2" />
            <geom type="mesh" contype="0" conaffinity="0" group="1" density="0" rgba="1 1 1 1" mesh="l_leg_pitch" />
            <body name="leg_l4_link" pos="-6.87185e-05 0 -0.284">
              <inertial pos="0.00696242 5.314e-05 -0.115499" quat="0.99996 -0.00125674 -0.00257659 -0.00848361" mass="1.62777" diaginertia="0.0124395 0.0122957 0.000978994" />
              <joint name="leg_l4_joint" pos="0 0 0" axis="0 1 0" range="0 2.53073" actuatorfrcrange="-180 180" damping="0.2" />
              <geom type="mesh" contype="0" conaffinity="0" group="1" density="0" rgba="1 1 1 1" mesh="l_knee" />
              <body name="leg_l5_link" pos="-0.000431636 0 -0.346">
                <inertial pos="0 0 0" quat="0.5 0.5 -0.5 0.5" mass="0.0719352" diaginertia="1.218e-05 6.92e-06 6.92e-06" />
                <joint name="leg_l5_joint" pos="0 0 0" axis="0 1 0" range="-0.872665 0.349066" actuatorfrcrange="-36 36" damping="0.2" />
                <geom type="mesh" contype="0" conaffinity="0" group="1" density="0" rgba="1 1 1 1" mesh="l_foot_pitch" />
                <body name="leg_l6_link">
                  <inertial pos="0.0373996 -2.2061e-06 -0.0389691" quat="1.14784e-05 0.71913 -5.49597e-06 0.694876" mass="0.501754" diaginertia="0.00177936 0.00163509 0.000396929" />
                  <joint name="leg_l6_joint" pos="0 0 0" axis="1 0 0" range="-0.261799 0.261799" actuatorfrcrange="-36 36" damping="0.2" />
                  <geom type="mesh" contype="0" conaffinity="0" group="1" density="0" rgba="1 1 1 1" mesh="l_foot_roll" />
                  <geom size="0.005" pos="0.17084 0.04773 -0.0595" />
                  <geom size="0.005" pos="-0.073164 0.04773 -0.0595" />
                  <geom size="0.005" pos="0.17084 -0.04773 -0.0595" />
                  <geom size="0.005" pos="-0.073164 -0.04773 -0.0595" />
                  <geom size="0.005" pos="0.17084 0 -0.0595" />
                  <geom size="0.005" pos="-0.073164 0 -0.0595" />
                </body>
              </body>
            </body>
          </body>
        </body>
      </body>
      <body name="leg_r1_link" pos="-0.0024999 -0.087 -0.066">
        <inertial pos="-0.00430146 2.709e-05 -0.00851195" quat="0.000746146 0.721814 0.00298446 0.69208" mass="1.71093" diaginertia="0.00371121 0.00277272 0.00205799" />
        <joint name="leg_r1_joint" pos="0 0 0" axis="1 0 0" range="-0.663225 0.314159" actuatorfrcrange="-180 180" damping="0.2" />
        <geom type="mesh" contype="0" conaffinity="0" group="1" density="0" rgba="1 1 1 1" mesh="r_leg_roll" />
        <body name="leg_r2_link">
          <inertial pos="0 0.00231118 -0.0906254" quat="0.717644 0.696411 1.34603e-05 -1.38707e-05" mass="0.580292" diaginertia="0.00223984 0.00146412 0.00123154" />
          <joint name="leg_r2_joint" pos="0 0 0" axis="0 0 1" range="-0.785398 0.872665" actuatorfrcrange="-100 100" damping="0.2" />
          <geom type="mesh" contype="0" conaffinity="0" group="1" density="0" rgba="1 1 1 1" mesh="r_leg_yaw" />
          <body name="leg_r3_link" pos="-4.88007e-05 0 -0.1287">
            <inertial pos="0.00208315 -0.0119964 -0.0841138" quat="0.619803 -0.0366218 0.0180205 0.783696" mass="4.50386" diaginertia="0.0396237 0.0389344 0.00980197" />
            <joint name="leg_r3_joint" pos="0 0 0" axis="0 1 0" range="-2.00713 1.5708" actuatorfrcrange="-100 100" damping="0.2" />
            <geom type="mesh" contype="0" conaffinity="0" group="1" density="0" rgba="1 1 1 1" mesh="r_leg_pitch" />
            <body name="leg_r4_link" pos="0.000147139 0 -0.284">
              <inertial pos="0.00743231 -5.343e-05 -0.115587" quat="0.999959 0.0012612 -0.00276098 0.00849144" mass="1.62656" diaginertia="0.012413 0.0122692 0.00097885" />
              <joint name="leg_r4_joint" pos="0 0 0" axis="0 1 0" range="0 2.53073" actuatorfrcrange="-180 180" damping="0.2" />
              <geom type="mesh" contype="0" conaffinity="0" group="1" density="0" rgba="1 1 1 1" mesh="r_knee" />
              <body name="leg_r5_link" pos="0.000119806 0 -0.346">
                <inertial pos="0 0 0" quat="0.5 0.5 -0.5 0.5" mass="0.0719352" diaginertia="1.218e-05 6.92e-06 6.92e-06" />
                <joint name="leg_r5_joint" pos="0 0 0" axis="0 1 0" range="-0.872665 0.349066" actuatorfrcrange="-36 36" damping="0.2" />
                <geom type="mesh" contype="0" conaffinity="0" group="1" density="0" rgba="1 1 1 1" mesh="r_foot_pitch" />
                <body name="leg_r6_link">
                  <inertial pos="0.037413 -2.2061e-06 -0.0389563" quat="1.14537e-05 0.719014 -5.52258e-06 0.694996" mass="0.501754" diaginertia="0.00177936 0.00163509 0.000396923" />
                  <joint name="leg_r6_joint" pos="0 0 0" axis="1 0 0" range="-0.261799 0.261799" actuatorfrcrange="-36 36" damping="0.2" />
                  <geom type="mesh" contype="0" conaffinity="0" group="1" density="0" rgba="1 1 1 1" mesh="r_foot_roll" />
                  <geom size="0.005" pos="0.17084 0.04773 -0.0595" />
                  <geom size="0.005" pos="-0.073164 0.04773 -0.0595" />
                  <geom size="0.005" pos="0.17084 -0.04773 -0.0595" />
                  <geom size="0.005" pos="-0.073164 -0.04773 -0.0595" />
                  <geom size="0.005" pos="0.17084 0 -0.0595" />
                  <geom size="0.005" pos="-0.073164 0 -0.0595" />
                </body>
              </body>
            </body>
          </body>
        </body>
      </body>
      <body name="zarm_l1_link" pos="-0.0174999 0.2927 0.4245">
        <inertial pos="-0.00083 -0.02218 0.00035" quat="0.507855 0.504005 -0.503768 0.484025" mass="0.962" diaginertia="0.00227032 0.0022507 0.000988974" />
        <joint name="zarm_l1_joint" pos="0 0 0" axis="0 1 0" range="-3.14159 1.5708" actuatorfrcrange="-100 100" damping="0.2" />
        <geom type="mesh" contype="0" conaffinity="0" group="1" density="0" rgba="1 1 1 1" mesh="l_arm_pitch" />
        <body name="zarm_l2_link">
          <inertial pos="-0.00791 0 -0.04655" quat="0.705843 -0.0422654 -0.0422654 0.705843" mass="0.57" diaginertia="0.00211 0.00163601 0.00121399" />
          <joint name="zarm_l2_joint" pos="0 0 0" axis="1 0 0" range="-0.349066 2.0944" actuatorfrcrange="-50 50" damping="0.2" />
          <geom type="mesh" contype="0" conaffinity="0" group="1" density="0" rgba="1 1 1 1" mesh="l_arm_roll" />
          <body name="zarm_l3_link">
            <inertial pos="0.00628 0.00107 -0.20878" quat="0.46857 -0.0547044 -0.0420079 0.88073" mass="1.65" diaginertia="0.00829713 0.00825256 0.00194031" />
            <joint name="zarm_l3_joint" pos="0 0 0" axis="0 0 1" range="-1.5708 1.5708" actuatorfrcrange="-39 39" damping="0.2" />
            <geom type="mesh" contype="0" conaffinity="0" group="1" density="0" rgba="1 1 1 1" mesh="l_arm_yaw" />
            <body name="zarm_l4_link" pos="0.02 0 -0.2837">
              <inertial pos="-0.01611 0.00143 -0.04857" quat="0.99579 0 0.0916646 0" mass="0.429" diaginertia="0.00136857 0.00114 0.000811432" />
              <joint name="zarm_l4_joint" pos="0 0 0" axis="0 1 0" range="-2.61799 0" actuatorfrcrange="-50 50" damping="0.2" />
              <geom type="mesh" contype="0" conaffinity="0" group="1" density="0" rgba="1 1 1 1" mesh="l_forearm" />
              <body name="zarm_l5_link" pos="-0.02 0 -0.127037">
                <inertial pos="-0.00207 0.00018 -0.05079" quat="0.70482 0.0568167 0.0568167 0.70482" mass="0.61" diaginertia="0.00146 0.00107649 0.000823509" />
                <joint name="zarm_l5_joint" pos="0 0 0" axis="0 0 1" range="-1.5708 1.5708" actuatorfrcrange="-12 12" damping="0.2" />
                <geom type="mesh" contype="0" conaffinity="0" group="1" density="0" rgba="1 1 1 1" mesh="l_hand_yaw" />
                <body name="zarm_l6_link" pos="0.0002 0 -0.106463">
                  <inertial pos="-0.00111 0.00335 -0.01335" quat="0 0.707107 0 0.707107" mass="0.331" diaginertia="0.00028 0.00027 0.00022" />
                  <joint name="zarm_l6_joint" pos="0 0 0" axis="1 0 0" range="-1.309 0.698132" actuatorfrcrange="-12 12" damping="0.2" />
                  <geom type="mesh" contype="0" conaffinity="0" group="1" density="0" rgba="1 1 1 1" mesh="l_hand_roll" />
                  <body name="zarm_l7_link" pos="0 0 -0.0210005">
                    <inertial pos="0.00185848 0.0101072 -0.090505" quat="0.961232 -0.0391052 -0.00682346 0.272869" mass="0.0542110173081966" diaginertia="0.000720114 0.00070104 0.000117174" />
                    <joint name="zarm_l7_joint" pos="0 0 0" axis="0 1 0" range="-0.698132 0.698132" actuatorfrcrange="-12 12" damping="0.2" />
                    <geom type="mesh" contype="0" conaffinity="0" group="1" density="0" rgba="1 1 1 1" mesh="l_hand_pitch" />
                    <geom size="0.005" pos="0 -0.03 -0.17" />
                    <geom pos="0 0 -0.07" quat="0.000563312 -0.000562864 0.706825 -0.707388" type="mesh" contype="0" conaffinity="0" group="1" rgba="0.75294 0.75294 0.75294 1" mesh="l_palm" />
                    <geom pos="0 0 -0.07" quat="0.000563312 -0.000562864 0.706825 -0.707388" type="mesh" rgba="0.75294 0.75294 0.75294 1" mesh="l_palm" />
                    <body name="l_thumb_prox" pos="0.024537 -0.023242 -0.0926135" quat="0.349346 -0.374856 0.58539 -0.628298">
                        <inertial pos="0.0017239 0.0051432 -0.031065" quat="0.663344 0.00923928 0.0504839 0.746552" mass="0.005" diaginertia="9e-05 7e-05 5e-05" />
                        <joint name="l_thumbCMC" pos="0 0 0" axis="0 1 0" limited="true" range="0 1.5708" damping="1.0" />
                        <geom type="mesh" contype="0" conaffinity="0" group="1" rgba="0.75294 0.75294 0.75294 1" mesh="l_thumb_prox" />
                        <geom type="mesh" rgba="0.75294 0.75294 0.75294 1" mesh="l_thumb_prox" />
                        <body name="l_thumb_dist" pos="0 0 0.013647" quat="0.878534 0.409665 -0.222652 0.103824">
                            <inertial pos="0.0017239 0.0051432 -0.031065" quat="0.663344 0.00923928 0.0504839 0.746552" mass="0.04" diaginertia="9e-05 7e-05 5e-05" />
                            <joint name="l_thumbMCP" pos="0 0 0" axis="-1 0 0" limited="true" range="0 0.8727" damping="1.0" />
                            <geom type="mesh" contype="0" conaffinity="0" group="1" rgba="0.75294 0.75294 0.75294 1" mesh="l_thumb_dist" />
                            <geom type="mesh" rgba="0.75294 0.75294 0.75294 1" mesh="l_thumb_dist" />
                        </body>
                    </body>
                    <body name="l_Index_prox" pos="0.0290066 -0.00223961 -0.158289" quat="-0.00514945 0.0303624 0.71714 -0.696248">
                        <inertial pos="0.0017239 0.0051432 -0.031065" quat="0.663344 0.00923928 0.0504839 0.746552" mass="0.008" diaginertia="9e-05 7e-05 5e-05" />
                        <joint name="l_indexMCP" pos="0 0 0" axis="1 0 0" limited="true" range="0 1.309" damping="1.0" />
                        <geom type="mesh" contype="0" conaffinity="0" group="1" rgba="0.75294 0.75294 0.75294 1" mesh="l_Index_prox" />
                        <geom type="mesh" rgba="0.75294 0.75294 0.75294 1" mesh="l_Index_prox" />
                        <body name="l_index_dist" pos="0 0.035 0" quat="0.995322 0.0966141 0 0">
                            <inertial pos="0.0017239 0.0051432 -0.031065" quat="0.663344 0.00923928 0.0504839 0.746552" mass="0.011" diaginertia="9e-05 7e-05 5e-05" />
                            <joint name="l_indexPIP" pos="0 0 0" axis="1 0 0" limited="true" range="0 2.0944" damping="1.0" />
                            <geom type="mesh" contype="0" conaffinity="0" group="1" rgba="0.75294 0.75294 0.75294 1" mesh="l_index_dist" />
                            <geom type="mesh" rgba="0.75294 0.75294 0.75294 1" mesh="l_index_dist" />
                        </body>
                    </body>
                    <body name="l_middle_prox" pos="0.00799729 0.00170995 -0.162285" quat="0.000563312 -0.000562864 0.706825 -0.707388">
                        <inertial pos="0.0017239 0.0051432 -0.031065" quat="0.663344 0.00923928 0.0504839 0.746552" mass="0.011" diaginertia="9e-05 7e-05 5e-05" />
                        <joint name="l_middleMCP" pos="0 0 0" axis="1 0 0" limited="true" range="0 1.309" damping="1.0" />
                        <geom type="mesh" contype="0" conaffinity="0" group="1" rgba="0.75294 0.75294 0.75294 1" mesh="l_middle_prox" />
                        <geom type="mesh" rgba="0.75294 0.75294 0.75294 1" mesh="l_middle_prox" />
                        <body name="l_middle_dist" pos="0 0.042 0" quat="0.995791 0.0916562 0 0">
                            <inertial pos="0.0017239 0.0051432 -0.031065" quat="0.663344 0.00923928 0.0504839 0.746552" mass="0.011" diaginertia="9e-05 7e-05 5e-05" />
                            <joint name="l_middlePIP" pos="0 0 0" axis="1 0 0" limited="true" range="0 2.0944" damping="1.0" />
                            <geom type="mesh" contype="0" conaffinity="0" group="1" rgba="0.75294 0.75294 0.75294 1" mesh="l_middle_dist" />
                            <geom type="mesh" rgba="0.75294 0.75294 0.75294 1" mesh="l_middle_dist" />
                        </body>
                    </body>
                    <body name="l_ring_prox" pos="-0.0131057 0.00169173 -0.160292" quat="0.00657584 -0.0314397 0.71003 -0.703438">
                        <inertial pos="0.0017239 0.0051432 -0.031065" quat="0.663344 0.00923928 0.0504839 0.746552" mass="0.011" diaginertia="9e-05 7e-05 5e-05" />
                        <joint name="l_ringMCP" pos="0 0 0" axis="1 0 0" limited="true" range="0 1.309" damping="1.0" />
                        <geom type="mesh" contype="0" conaffinity="0" group="1" rgba="0.75294 0.75294 0.75294 1" mesh="l_ring_prox" />
                        <geom type="mesh" rgba="0.75294 0.75294 0.75294 1" mesh="l_ring_prox" />
                        <body name="l_ring_dist" pos="0 0.042 0" quat="0.996565 0.08282 0 0">
                            <inertial pos="0.0017239 0.0051432 -0.031065" quat="0.663344 0.00923928 0.0504839 0.746552" mass="0.008" diaginertia="9e-05 7e-05 5e-05" />
                            <joint name="l_ringPIP" pos="0 0 0" axis="1 0 0" limited="true" range="0 2.0944" damping="1.0" />
                            <geom type="mesh" contype="0" conaffinity="0" group="1" rgba="0.75294 0.75294 0.75294 1" mesh="l_ring_dist" />
                            <geom type="mesh" rgba="0.75294 0.75294 0.75294 1" mesh="l_ring_dist" />
                        </body>
                    </body>
                    <body name="l_little_prox" pos="-0.0337273 -0.00233593 -0.153775" quat="-0.00616957 -0.0436547 0.715503 -0.697217">
                        <inertial pos="-5.4618e-07 0.016662 0.00040738" quat="0.519207 0.480025 -0.479962 0.519265" mass="0.008" diaginertia="9e-05 7e-05 5e-05" />
                        <joint name="l_littleMCP" pos="0 0 0" axis="1 0 0" limited="true" range="0 1.309" damping="1.0" />
                        <geom type="mesh" contype="0" conaffinity="0" group="1" rgba="1 1 1 1" mesh="l_little_prox" />
                        <geom type="mesh" rgba="1 1 1 1" mesh="l_little_prox" />
                        <body name="l_little_dist" pos="0 0.035 0" quat="0.994856 0.101296 0 0">
                            <inertial pos="0.0017239 0.0051432 -0.031065" quat="0.663344 0.00923928 0.0504839 0.746552" mass="0.008" diaginertia="9e-05 7e-05 5e-05" />
                            <joint name="l_littlePIP" pos="0 0 0" axis="1 0 0" limited="true" range="0 2.0944" damping="1.0" />
                            <geom type="mesh" contype="0" conaffinity="0" group="1" rgba="0.75294 0.75294 0.75294 1" mesh="l_little_dist" />
                            <geom type="mesh" rgba="0.75294 0.75294 0.75294 1" mesh="l_little_dist" />
                        </body>
                    </body>
                  </body>
                </body>
              </body>
            </body>
          </body>
        </body>
      </body>
      <body name="zarm_r1_link" pos="-0.0174999 -0.2927 0.4245">
        <inertial pos="-0.00083 0.02218 0.00035" quat="0.504005 0.507855 -0.484025 0.503768" mass="0.962" diaginertia="0.00227032 0.0022507 0.000988974" />
        <joint name="zarm_r1_joint" pos="0 0 0" axis="0 1 0" range="-3.14159 1.5708" actuatorfrcrange="-100 100" damping="0.2" />
        <geom type="mesh" contype="0" conaffinity="0" group="1" density="0" rgba="1 1 1 1" mesh="r_arm_pitch" />
        <body name="zarm_r2_link">
          <inertial pos="-0.00791 0 -0.04655" quat="0.705843 -0.0422654 -0.0422654 0.705843" mass="0.57" diaginertia="0.00211 0.00163601 0.00121399" />
          <joint name="zarm_r2_joint" pos="0 0 0" axis="1 0 0" range="-2.0944 0.349066" actuatorfrcrange="-50 50" damping="0.2" />
          <geom type="mesh" contype="0" conaffinity="0" group="1" density="0" rgba="1 1 1 1" mesh="r_arm_roll" />
          <body name="zarm_r3_link">
            <inertial pos="0.00628 -0.00107 -0.20878" quat="0.88073 -0.0420079 -0.0547044 0.46857" mass="1.65" diaginertia="0.00829713 0.00825256 0.00194031" />
            <joint name="zarm_r3_joint" pos="0 0 0" axis="0 0 1" range="-1.5708 1.5708" actuatorfrcrange="-39 39" damping="0.2" />
            <geom type="mesh" contype="0" conaffinity="0" group="1" density="0" rgba="1 1 1 1" mesh="r_arm_yaw" />
            <body name="zarm_r4_link" pos="0.02 0 -0.2837">
              <inertial pos="-0.01611 -0.00143 -0.04857" quat="0.99579 0 0.0916646 0" mass="0.429" diaginertia="0.00136857 0.00114 0.000811432" />
              <joint name="zarm_r4_joint" pos="0 0 0" axis="0 1 0" range="-2.61799 0" actuatorfrcrange="-50 50" damping="0.2" />
              <geom type="mesh" contype="0" conaffinity="0" group="1" density="0" rgba="1 1 1 1" mesh="r_forearm" />
              <body name="zarm_r5_link" pos="-0.02 0 -0.127037">
                <inertial pos="-0.00207 -0.00018 -0.05079" quat="0.70482 0.0568167 0.0568167 0.70482" mass="0.61" diaginertia="0.00146 0.00107649 0.000823509" />
                <joint name="zarm_r5_joint" pos="0 0 0" axis="0 0 1" range="-1.5708 1.5708" actuatorfrcrange="-12 12" damping="0.2" />
                <geom type="mesh" contype="0" conaffinity="0" group="1" density="0" rgba="1 1 1 1" mesh="r_hand_yaw" />
                <body name="zarm_r6_link" pos="0 0 -0.106463">
                  <inertial pos="-0.00111 -0.00335 -0.01335" quat="0 0.707107 0 0.707107" mass="0.331" diaginertia="0.00028 0.00027 0.00022" />
                  <joint name="zarm_r6_joint" pos="0 0 0" axis="1 0 0" range="-0.698132 1.309" actuatorfrcrange="-12 12" damping="0.2" />
                  <geom type="mesh" contype="0" conaffinity="0" group="1" density="0" rgba="1 1 1 1" mesh="r_hand_roll" />
                  <body name="zarm_r7_link" pos="0 0 -0.021">
                    <inertial pos="0.00185848 -0.0101072 -0.090505" quat="0.956166 0.0488773 -0.0039771 -0.288691" mass="0.0542110173081966" diaginertia="0.000700271 0.000682658 0.000115399" />
                    <joint name="zarm_r7_joint" pos="0 0 0" axis="0 1 0" range="-0.698132 0.698132" actuatorfrcrange="-12 12" damping="0.2" />
                    <geom type="mesh" contype="0" conaffinity="0" group="1" density="0" rgba="1 1 1 1" mesh="r_hand_pitch" />
                    <geom size="0.005" pos="0 0.03 -0.17" />
                    <geom pos="0 0 -0.07" quat="0.707388 -0.706825 0 0" type="mesh" contype="0" conaffinity="0" group="1" rgba="0.75294 0.75294 0.75294 1" mesh="r_palm" />
                    <geom pos="0 0 -0.07" quat="0.707388 -0.706825 0 0" type="mesh" rgba="0.75294 0.75294 0.75294 1" mesh="r_palm" />
                    <body name="r_thumb_prox" pos="0.0245 0.0216473 -0.0941828" quat="0.685709 -0.685164 -0.173784 0.173645">
                        <inertial pos="0.0062041 -7.9383e-08 0.0015306" quat="0.486357 0.51328 0.51328 0.486357" mass="0.005" diaginertia="9e-05 7e-05 5e-05" />
                        <joint name="r_thumbCMC" pos="0 0 0" axis="0 -1 0" limited="true" range="0 1.5708" damping="1.0" />
                        <geom type="mesh" contype="0" conaffinity="0" group="1" rgba="1 1 1 1" mesh="r_thumb_prox" />
                        <geom type="mesh" rgba="1 1 1 1" mesh="r_thumb_prox" />
                        <body name="r_thumb_dist" pos="0.013647 0 0" quat="0.878532 -0.103824 0.222655 -0.409666">
                            <inertial pos="0.0083564 0.037204 -3.5884e-07" quat="0.707048 0.706981 0.0114675 0.0113604" mass="0.04" diaginertia="9e-05 7e-05 5e-05" />
                            <joint name="r_thumbMCP" pos="0 0 0" axis="0 0 1" limited="true" range="0 0.87266" damping="1.0" />
                            <geom type="mesh" contype="0" conaffinity="0" group="1" rgba="0.75294 0.75294 0.75294 1" mesh="r_thumb_dist" />
                            <geom type="mesh" rgba="0.75294 0.75294 0.75294 1" mesh="r_thumb_dist" />
                        </body>
                    </body>
                    <body name="r_index_prox" pos="0.029003 -0.00387854 -0.158234" quat="0.670793 -0.740977 -0.0307155 0.00677999">
                        <inertial pos="-5.571e-07 0.016609 0.00045746" quat="0.518542 0.480744 -0.480679 0.518602" mass="0.008" diaginertia="9e-05 7e-05 5e-05" />
                        <joint name="r_indexMCP" pos="0 0 0" axis="1 0 0" limited="true" range="0 1.309" damping="1.0" />
                        <geom type="mesh" contype="0" conaffinity="0" group="1" rgba="0.75294 0.75294 0.75294 1" mesh="r_index_prox" />
                        <geom type="mesh" rgba="0.75294 0.75294 0.75294 1" mesh="r_index_prox" />
                        <body name="r_index_dist" pos="0 0.035 0" quat="0.995322 0.0966141 0 0">
                            <inertial pos="5.9401e-06 0.025449 0.003278" quat="0.464988 0.533023 -0.533381 0.463873" mass="0.011" diaginertia="9e-05 7e-05 5e-05" />
                            <joint name="r_indexPIP" pos="0 0 0" axis="1 0 0" limited="true" range="0 2.0944" damping="1.0" />
                            <geom type="mesh" contype="0" conaffinity="0" group="1" rgba="0.75294 0.75294 0.75294 1" mesh="r_index_dist" />
                            <geom type="mesh" rgba="0.75294 0.75294 0.75294 1" mesh="r_index_dist" />
                        </body>
                    </body>
                    <body name="r_middle_prox" pos="0.008 -0.00813059 -0.161942" quat="0.68229 -0.731082 0 0">
                        <inertial pos="2.3779e-07 0.020205 0.00053993" quat="0.51393 0.485582 -0.485656 0.514028" mass="0.011" diaginertia="9e-05 7e-05 5e-05" />
                        <joint name="r_middleMCP" pos="0 0 0" axis="1 0 0" limited="true" range="0 1.309" damping="1.0" />
                        <geom type="mesh" contype="0" conaffinity="0" group="1" rgba="0.75294 0.75294 0.75294 1" mesh="r_middle_prox" />
                        <geom type="mesh" rgba="0.75294 0.75294 0.75294 1" mesh="r_middle_prox" />
                        <body name="r_middle_dist" pos="0 0.042 0" quat="0.995791 0.0916562 0 0">
                            <inertial pos="5.9404e-06 0.025449 0.003278" quat="0.464985 0.533021 -0.533384 0.463874" mass="0.011" diaginertia="9e-05 7e-05 5e-05" />
                            <joint name="r_middlePIP" pos="0 0 0" axis="1 0 0" limited="true" range="0 2.0944" damping="1.0" />
                            <geom type="mesh" contype="0" conaffinity="0" group="1" rgba="0.75294 0.75294 0.75294 1" mesh="r_middle_dist" />
                            <geom type="mesh" rgba="0.75294 0.75294 0.75294 1" mesh="r_middle_dist" />
                        </body>
                    </body>
                    <body name="r_ring_prox" pos="-0.013103 -0.00800697 -0.159953" quat="0.678234 -0.734173 0.0306456 -0.00708951">
                        <inertial pos="2.4507e-07 0.020236 0.00042373" quat="0.514454 0.485027 -0.48511 0.514552" mass="0.011" diaginertia="9e-05 7e-05 5e-05" />
                        <joint name="r_ringMCP" pos="0 0 0" axis="1 0 0" limited="true" range="0 1.309" damping="1.0" />
                        <geom type="mesh" contype="0" conaffinity="0" group="1" rgba="0.75294 0.75294 0.75294 1" mesh="r_ring_prox" />
                        <geom type="mesh" rgba="0.75294 0.75294 0.75294 1" mesh="r_ring_prox" />
                        <body name="r_ring_dist" pos="0 0.042 0" quat="0.996565 0.08282 0 0">
                            <inertial pos="5.5799e-07 0.020388 0.0029077" quat="0.461493 0.535513 -0.535785 0.46172" mass="0.008" diaginertia="9e-05 7e-05 5e-05" />
                            <joint name="r_ringPIP" pos="0 0 0" axis="1 0 0" limited="true" range="0 2.0944" damping="1.0" />
                            <geom type="mesh" contype="0" conaffinity="0" group="1" rgba="0.75294 0.75294 0.75294 1" mesh="r_ring_dist" />
                            <geom type="mesh" rgba="0.75294 0.75294 0.75294 1" mesh="r_ring_dist" />
                        </body>
                    </body>
                    <body name="r_little_prox" pos="-0.033731 -0.00356722 -0.15373" quat="0.671815 -0.739434 0.0432936 0.00521716">
                        <inertial pos="-5.4618e-07 0.016662 0.00040738" quat="0.519207 0.480025 -0.479962 0.519265" mass="0.008" diaginertia="9e-05 7e-05 5e-05" />
                        <joint name="r_littleMCP" pos="0 0 0" axis="1 0 0" limited="true" range="0 1.309" damping="1.0" />
                        <geom type="mesh" contype="0" conaffinity="0" group="1" rgba="0.75294 0.75294 0.75294 1" mesh="r_little_prox" />
                        <geom type="mesh" rgba="0.75294 0.75294 0.75294 1" mesh="r_little_prox" />
                        <body name="r_little_dist" pos="0 0.035 0" quat="0.994856 0.11296 0 0">
                            <inertial pos="1.062e-05 0.017869 0.0020864" quat="0.468752 0.529699 -0.53072 0.466934" mass="0.008" diaginertia="9e-05 7e-05 5e-05" />
                            <joint name="r_littlePIP" pos="0 0 0" axis="1 0 0" limited="true" range="0 2.0944" damping="1.0" />
                            <geom type="mesh" contype="0" conaffinity="0" group="1" rgba="0.75294 0.75294 0.75294 1" mesh="r_little_dist" />
                            <geom type="mesh" rgba="0.75294 0.75294 0.75294 1" mesh="r_little_dist" />
                        </body>
                    </body>
                  </body>
                </body>
              </body>
            </body>
          </body>
        </body>
      </body>
      <body name="zhead_1_link" pos="-0.0184999 0 0.6014">
        <inertial pos="2e-05 0.00605 -0.01052" mass="0.35" diaginertia="9e-05 7e-05 5e-05" />
        <joint name="zhead_1_joint" pos="0 0 0" axis="0 0 1" range="-1.5708 1.5708" actuatorfrcrange="-1.5 1.5" damping="0.2" />
        <geom type="mesh" contype="0" conaffinity="0" group="1" density="0" rgba="1 1 1 1" mesh="head_yaw" />
        <body name="zhead_2_link">
          <inertial pos="0.0277019 -0.000890845 0.113292" quat="0.385654 -0.133514 -0.0333113 0.912324" mass="0.865" diaginertia="0.00468715 0.00458653 0.00311717" />
          <joint name="zhead_2_joint" pos="0 0 0" axis="0 1 0" range="-0.523599 0.523599" actuatorfrcrange="-12 12" damping="0.2" />
          <geom type="mesh" contype="0" conaffinity="0" group="1" density="0" rgba="1 1 1 1" mesh="head_pitch" />
          <geom pos="0.096751 0.0175003 0.125953" quat="0.970296 0 0.241922 0" type="mesh" contype="0" conaffinity="0" group="1" density="0" rgba="1 1 1 1" mesh="camera" />
          <geom pos="0.0217799 0 0.105417" quat="0.993413 0 0.114591 0" type="mesh" contype="0" conaffinity="0" group="1" density="0" rgba="1 1 1 1" mesh="radar" />
        </body>
      </body>
    </body>
  </worldbody>
  <actuator>
    <motor gear="1" joint="leg_l1_joint" name="leg_l1_joint_motor" ctrllimited="true" ctrlrange="-180 180" />
    <motor gear="1" joint="leg_l2_joint" name="leg_l2_joint_motor" ctrllimited="true" ctrlrange="-100 100" />
    <motor gear="1" joint="leg_l3_joint" name="leg_l3_joint_motor" ctrllimited="true" ctrlrange="-100 100" />
    <motor gear="1" joint="leg_l4_joint" name="leg_l4_joint_motor" ctrllimited="true" ctrlrange="-180 180" />
    <motor gear="1" joint="leg_l5_joint" name="leg_l5_joint_motor" ctrllimited="true" ctrlrange="-36 36" />
    <motor gear="1" joint="leg_l6_joint" name="leg_l6_joint_motor" ctrllimited="true" ctrlrange="-36 36" />
    <motor gear="1" joint="leg_r1_joint" name="leg_r1_joint_motor" ctrllimited="true" ctrlrange="-180 180" />
    <motor gear="1" joint="leg_r2_joint" name="leg_r2_joint_motor" ctrllimited="true" ctrlrange="-100 100" />
    <motor gear="1" joint="leg_r3_joint" name="leg_r3_joint_motor" ctrllimited="true" ctrlrange="-100 100" />
    <motor gear="1" joint="leg_r4_joint" name="leg_r4_joint_motor" ctrllimited="true" ctrlrange="-180 180" />
    <motor gear="1" joint="leg_r5_joint" name="leg_r5_joint_motor" ctrllimited="true" ctrlrange="-36 36" />
    <motor gear="1" joint="leg_r6_joint" name="leg_r6_joint_motor" ctrllimited="true" ctrlrange="-36 36" />
    <motor gear="1" joint="zarm_l1_joint" name="zarm_l1_joint_motor" ctrllimited="true" ctrlrange="-100 100" />
    <motor gear="1" joint="zarm_l2_joint" name="zarm_l2_joint_motor" ctrllimited="true" ctrlrange="-50 50" />
    <motor gear="1" joint="zarm_l3_joint" name="zarm_l3_joint_motor" ctrllimited="true" ctrlrange="-39 39" />
    <motor gear="1" joint="zarm_l4_joint" name="zarm_l4_joint_motor" ctrllimited="true" ctrlrange="-50 50" />
    <motor gear="1" joint="zarm_l5_joint" name="zarm_l5_joint_motor" ctrllimited="true" ctrlrange="-12 12" />
    <motor gear="1" joint="zarm_l6_joint" name="zarm_l6_joint_motor" ctrllimited="true" ctrlrange="-12 12" />
    <motor gear="1" joint="zarm_l7_joint" name="zarm_l7_joint_motor" ctrllimited="true" ctrlrange="-12 12" />
    <motor gear="1" joint="zarm_r1_joint" name="zarm_r1_joint_motor" ctrllimited="true" ctrlrange="-100 100" />
    <motor gear="1" joint="zarm_r2_joint" name="zarm_r2_joint_motor" ctrllimited="true" ctrlrange="-50 50" />
    <motor gear="1" joint="zarm_r3_joint" name="zarm_r3_joint_motor" ctrllimited="true" ctrlrange="-39 39" />
    <motor gear="1" joint="zarm_r4_joint" name="zarm_r4_joint_motor" ctrllimited="true" ctrlrange="-50 50" />
    <motor gear="1" joint="zarm_r5_joint" name="zarm_r5_joint_motor" ctrllimited="true" ctrlrange="-12 12" />
    <motor gear="1" joint="zarm_r6_joint" name="zarm_r6_joint_motor" ctrllimited="true" ctrlrange="-12 12" />
    <motor gear="1" joint="zarm_r7_joint" name="zarm_r7_joint_motor" ctrllimited="true" ctrlrange="-12 12" />
    <motor gear="1" joint="zhead_1_joint" name="zhead_1_joint_motor" ctrllimited="true" ctrlrange="-1.5 1.5" />
    <motor gear="1" joint="zhead_2_joint" name="zhead_2_joint_motor" ctrllimited="true" ctrlrange="-12 12" />
    <position gear="1" joint="l_thumbCMC" name="l_thumbCMC_motor" ctrllimited="true" ctrlrange="0 1.5708" />
    <position gear="1" joint="l_thumbMCP" name="l_thumbMCP_motor" ctrllimited="true" ctrlrange="0 0.872" />
    <position gear="1" joint="l_indexMCP" name="l_indexMCP_motor" ctrllimited="true" ctrlrange="0 1.309" />
    <position gear="1" joint="l_indexPIP" name="l_indexPIP_motor" ctrllimited="true" ctrlrange="0 1.25" />
    <position gear="1" joint="l_middleMCP" name="l_middleMCP_motor" ctrllimited="true" ctrlrange="0 1.309" />
    <position gear="1" joint="l_middlePIP" name="l_middlePIP_motor" ctrllimited="true" ctrlrange="0 1.25" />
    <position gear="1" joint="l_ringMCP" name="l_ringMCP_motor" ctrllimited="true" ctrlrange="0 1.309" />
    <position gear="1" joint="l_ringPIP" name="l_ringPIP_motor" ctrllimited="true" ctrlrange="0 1.25" />
    <position gear="1" joint="l_littleMCP" name="l_littleMCP_motor" ctrllimited="true" ctrlrange="0 1.309" />
    <position gear="1" joint="l_littlePIP" name="l_littlePIP_motor" ctrllimited="true" ctrlrange="0 1.25" />
    <position gear="1" joint="r_thumbCMC" name="r_thumbCMC_motor" ctrllimited="true" ctrlrange="0 1.5708" />
    <position gear="1" joint="r_thumbMCP" name="r_thumbMCP_motor" ctrllimited="true" ctrlrange="0 0.872" />
    <position gear="1" joint="r_indexMCP" name="r_indexMCP_motor" ctrllimited="true" ctrlrange="0 1.3095" />
    <position gear="1" joint="r_indexPIP" name="r_indexPIP_motor" ctrllimited="true" ctrlrange="0 1.25" />
    <position gear="1" joint="r_middleMCP" name="r_middleMCP_motor" ctrllimited="true" ctrlrange="0 1.309" />
    <position gear="1" joint="r_middlePIP" name="r_middlePIP_motor" ctrllimited="true" ctrlrange="0 1.25" />
    <position gear="1" joint="r_ringMCP" name="r_ringMCP_motor" ctrllimited="true" ctrlrange="0 1.309" />
    <position gear="1" joint="r_ringPIP" name="r_ringPIP_motor" ctrllimited="true" ctrlrange="0 1.25" />
    <position gear="1" joint="r_littleMCP" name="r_littleMCP_motor" ctrllimited="true" ctrlrange="0 1.309" />
    <position gear="1" joint="r_littlePIP" name="r_littlePIP_motor" ctrllimited="true" ctrlrange="0 1.25" />
  </actuator>
  <sensor>
    <accelerometer name="BodyAcc" site="imu" />
    <velocimeter name="BodyVel" site="imu" />
    <gyro name="BodyGyro" site="imu" />
    <framepos name="BodyPos" objtype="site" objname="imu" />
    <framequat name="BodyQuat" objtype="site" objname="imu" />
    <jointpos name="leg_l1_joint_pos" joint="leg_l1_joint" />
    <jointpos name="leg_l2_joint_pos" joint="leg_l2_joint" />
    <jointpos name="leg_l3_joint_pos" joint="leg_l3_joint" />
    <jointpos name="leg_l4_joint_pos" joint="leg_l4_joint" />
    <jointpos name="leg_l5_joint_pos" joint="leg_l5_joint" />
    <jointpos name="leg_l6_joint_pos" joint="leg_l6_joint" />
    <jointpos name="leg_r1_joint_pos" joint="leg_r1_joint" />
    <jointpos name="leg_r2_joint_pos" joint="leg_r2_joint" />
    <jointpos name="leg_r3_joint_pos" joint="leg_r3_joint" />
    <jointpos name="leg_r4_joint_pos" joint="leg_r4_joint" />
    <jointpos name="leg_r5_joint_pos" joint="leg_r5_joint" />
    <jointpos name="leg_r6_joint_pos" joint="leg_r6_joint" />
    <jointpos name="zarm_l1_joint_pos" joint="zarm_l1_joint" />
    <jointpos name="zarm_l2_joint_pos" joint="zarm_l2_joint" />
    <jointpos name="zarm_l3_joint_pos" joint="zarm_l3_joint" />
    <jointpos name="zarm_l4_joint_pos" joint="zarm_l4_joint" />
    <jointpos name="zarm_l5_joint_pos" joint="zarm_l5_joint" />
    <jointpos name="zarm_l6_joint_pos" joint="zarm_l6_joint" />
    <jointpos name="zarm_l7_joint_pos" joint="zarm_l7_joint" />
    <jointpos name="zarm_r1_joint_pos" joint="zarm_r1_joint" />
    <jointpos name="zarm_r2_joint_pos" joint="zarm_r2_joint" />
    <jointpos name="zarm_r3_joint_pos" joint="zarm_r3_joint" />
    <jointpos name="zarm_r4_joint_pos" joint="zarm_r4_joint" />
    <jointpos name="zarm_r5_joint_pos" joint="zarm_r5_joint" />
    <jointpos name="zarm_r6_joint_pos" joint="zarm_r6_joint" />
    <jointpos name="zarm_r7_joint_pos" joint="zarm_r7_joint" />
    <jointpos name="zhead_1_joint_pos" joint="zhead_1_joint" />
    <jointpos name="zhead_2_joint_pos" joint="zhead_2_joint" />
    <jointpos name="l_thumbCMC_pos" joint="l_thumbCMC" />
    <jointpos name="l_thumbMCP_pos" joint="l_thumbMCP" />
    <jointpos name="l_indexMCP_pos" joint="l_indexMCP" />
    <jointpos name="l_indexPIP_pos" joint="l_indexPIP" />
    <jointpos name="l_middleMCP_pos" joint="l_middleMCP" />
    <jointpos name="l_middlePIP_pos" joint="l_middlePIP" />
    <jointpos name="l_ringMCP_pos" joint="l_ringMCP" />
    <jointpos name="l_ringPIP_pos" joint="l_ringPIP" />
    <jointpos name="l_littleMCP_pos" joint="l_littleMCP" />
    <jointpos name="l_littlePIP_pos" joint="l_littlePIP" />
    <jointpos name="r_thumbCMC_pos" joint="r_thumbCMC" />
    <jointpos name="r_thumbMCP_pos" joint="r_thumbMCP" />
    <jointpos name="r_indexMCP_pos" joint="r_indexMCP" />
    <jointpos name="r_indexPIP_pos" joint="r_indexPIP" />
    <jointpos name="r_middleMCP_pos" joint="r_middleMCP" />
    <jointpos name="r_middlePIP_pos" joint="r_middlePIP" />
    <jointpos name="r_ringMCP_pos" joint="r_ringMCP" />
    <jointpos name="r_ringPIP_pos" joint="r_ringPIP" />
    <jointpos name="r_littleMCP_pos" joint="r_littleMCP" />
    <jointpos name="r_littlePIP_pos" joint="r_littlePIP" />
    <jointvel name="leg_l1_joint_vel" joint="leg_l1_joint" />
    <jointvel name="leg_l2_joint_vel" joint="leg_l2_joint" />
    <jointvel name="leg_l3_joint_vel" joint="leg_l3_joint" />
    <jointvel name="leg_l4_joint_vel" joint="leg_l4_joint" />
    <jointvel name="leg_l5_joint_vel" joint="leg_l5_joint" />
    <jointvel name="leg_l6_joint_vel" joint="leg_l6_joint" />
    <jointvel name="leg_r1_joint_vel" joint="leg_r1_joint" />
    <jointvel name="leg_r2_joint_vel" joint="leg_r2_joint" />
    <jointvel name="leg_r3_joint_vel" joint="leg_r3_joint" />
    <jointvel name="leg_r4_joint_vel" joint="leg_r4_joint" />
    <jointvel name="leg_r5_joint_vel" joint="leg_r5_joint" />
    <jointvel name="leg_r6_joint_vel" joint="leg_r6_joint" />
    <jointvel name="zarm_l1_joint_vel" joint="zarm_l1_joint" />
    <jointvel name="zarm_l2_joint_vel" joint="zarm_l2_joint" />
    <jointvel name="zarm_l3_joint_vel" joint="zarm_l3_joint" />
    <jointvel name="zarm_l4_joint_vel" joint="zarm_l4_joint" />
    <jointvel name="zarm_l5_joint_vel" joint="zarm_l5_joint" />
    <jointvel name="zarm_l6_joint_vel" joint="zarm_l6_joint" />
    <jointvel name="zarm_l7_joint_vel" joint="zarm_l7_joint" />
    <jointvel name="zarm_r1_joint_vel" joint="zarm_r1_joint" />
    <jointvel name="zarm_r2_joint_vel" joint="zarm_r2_joint" />
    <jointvel name="zarm_r3_joint_vel" joint="zarm_r3_joint" />
    <jointvel name="zarm_r4_joint_vel" joint="zarm_r4_joint" />
    <jointvel name="zarm_r5_joint_vel" joint="zarm_r5_joint" />
    <jointvel name="zarm_r6_joint_vel" joint="zarm_r6_joint" />
    <jointvel name="zarm_r7_joint_vel" joint="zarm_r7_joint" />
    <jointvel name="zhead_1_joint_vel" joint="zhead_1_joint" />
    <jointvel name="zhead_2_joint_vel" joint="zhead_2_joint" />
    <jointvel name="l_thumbCMC_vel" joint="l_thumbCMC" />
    <jointvel name="l_thumbMCP_vel" joint="l_thumbMCP" />
    <jointvel name="l_indexMCP_vel" joint="l_indexMCP" />
    <jointvel name="l_indexPIP_vel" joint="l_indexPIP" />
    <jointvel name="l_middleMCP_vel" joint="l_middleMCP" />
    <jointvel name="l_middlePIP_vel" joint="l_middlePIP" />
    <jointvel name="l_ringMCP_vel" joint="l_ringMCP" />
    <jointvel name="l_ringPIP_vel" joint="l_ringPIP" />
    <jointvel name="l_littleMCP_vel" joint="l_littleMCP" />
    <jointvel name="l_littlePIP_vel" joint="l_littlePIP" />
    <jointvel name="r_thumbCMC_vel" joint="r_thumbCMC" />
    <jointvel name="r_thumbMCP_vel" joint="r_thumbMCP" />
    <jointvel name="r_indexMCP_vel" joint="r_indexMCP" />
    <jointvel name="r_indexPIP_vel" joint="r_indexPIP" />
    <jointvel name="r_middleMCP_vel" joint="r_middleMCP" />
    <jointvel name="r_middlePIP_vel" joint="r_middlePIP" />
    <jointvel name="r_ringMCP_vel" joint="r_ringMCP" />
    <jointvel name="r_ringPIP_vel" joint="r_ringPIP" />
    <jointvel name="r_littleMCP_vel" joint="r_littleMCP" />
    <jointvel name="r_littlePIP_vel" joint="r_littlePIP" />
  </sensor>
</mujoco>
